Workbook
Name a: #REF!

Sheet Assumption Sheet
B1: ='Balance Sheet'!B1 -> Name of Company
B3: PROFIT & LOSS ASSUMPTION - Input no as per your industry
B5: Expenses
A7: 1 | B7: Direct Expenses | D7: FY 23 | E7: FY 24 | F7: FY 1 | G7: FY 2 | H7: FY 3 | I7: FY 4 | J7: FY 5
B8: Manufacturing Costs | C8: % of Sales
B9: Direct labour | C9: % of Sales
B10: Factory expenses | C10: Fixed Cost - INR /per annum
A12: 1 | B12: Marketing Costs | D12: FY 23 | E12: FY 24 | F12: FY 1 | G12: FY 2 | H12: FY 3 | I12: FY 4 | J12: FY 5
B13: Branding and Marketing | C13: INR/Per Annum
B14: Digital Marketing | C14: INR/Per Annum
B15: Traditional Marketing | C15: INR/Per Annum
B16: Total | E16: =SUM(E13:E15) -> 0 | F16: =SUM(F13:F15) -> 0 | G16: =SUM(G13:G15) -> 0 | H16: =SUM(H13:H15) -> 0 | I16: =SUM(I13:I15) -> 0 | J16: =SUM(J13:J15) -> 0
A18: 2 | B18: General & Administrative Expenses | D18: FY 23 | E18: FY 24 | F18: FY 1 | G18: FY 2 | H18: FY 3 | I18: FY 4 | J18: FY 5
B19: Warehouse Rent | C19: INR/Per Annum | G19: =F19*(1+$G$29) -> 0 | H19: =G19*(1+$H$29) -> 0 | I19: =H19*(1+$I$29) -> 0 | J19: =I19*(1+$J$27) -> 0
B20: Office rent | C20: INR/Per annum | G20: =F20*(1+$G$29) -> 0 | H20: =G20*(1+$H$29) -> 0 | I20: =H20*(1+$I$29) -> 0 | J20: =I20*(1+$J$27) -> 0
B21: Utilities costs (Electricity, Communication) | C21: INR/Per annum | G21: =F21*(1+$G$29) -> 0 | H21: =G21*(1+$H$29) -> 0 | I21: =H21*(1+$I$29) -> 0 | J21: =I21*(1+$J$27) -> 0
B22: Infrastructure costs (admin, maintenance etc) | C22: INR/Per annum | G22: =F22*(1+$G$29) -> 0 | H22: =G22*(1+$H$29) -> 0 | I22: =H22*(1+$I$29) -> 0 | J22: =I22*(1+$J$27) -> 0
B23: Travel & Conveyance - Sales Team | C23: INR/Per Annum | G23: =F23*(1+$G$29) -> 0 | H23: =G23*(1+$H$29) -> 0 | I23: =H23*(1+$I$29) -> 0 | J23: =I23*(1+$J$27) -> 0
B24: Employee training & engagement | C24: INR/Per Annum | G24: =F24*(1+$G$29) -> 0 | H24: =G24*(1+$H$29) -> 0 | I24: =H24*(1+$I$29) -> 0 | J24: =I24*(1+$J$27) -> 0
B25: Printing & Stationery | C25: INR/Per Annum | G25: =F25*(1+$G$29) -> 0 | H25: =G25*(1+$H$29) -> 0 | I25: =H25*(1+$I$29) -> 0 | J25: =I25*(1+$J$27) -> 0
B26: Server & Hosting | C26: INR/Per Annum | G26: =F26*(1+$G$29) -> 0 | H26: =G26*(1+$H$29) -> 0 | I26: =H26*(1+$I$29) -> 0 | J26: =I26*(1+$J$27) -> 0
B27: Mis Cost | C27: % of gross sales | F27: 0.0025 | G27: 0.0025 | H27: 0.0025 | I27: 0.0025 | J27: 0.0025 | K27: as per your company
B29: Expenses Growth | C29: % growth | F29: na | G29: 0.05 | H29: 0.05 | I29: 0.05 | J29: 0.05 | K29: as per your company
A32: 3 | B32: Manpower Assumptions - HO (No of employees) | C32: Description | E32: FY 24 | F32: FY 1 | G32: FY 2 | H32: FY 3 | I32: FY 4 | J32: FY 5
B33: Management | C33: Co-founders
B34: CTO
B35: Technology
B36: Marketing Team
B37: Finance
B38: HR
B39: Admin
B40: Legal & Compliance
C41: Total Manpower | E41: =SUM(E33:E40) -> 0 | F41: =SUM(F33:F40) -> 0 | G41: =SUM(G33:G40) -> 0 | H41: =SUM(H33:H40) -> 0 | I41: =SUM(I33:I40) -> 0 | J41: =SUM(J33:J40) -> 0
B42: Salary per annum (per employee) | E42: FY 24 | F42: FY 1 | G42: FY 2 | H42: FY 3 | I42: FY 4 | J42: FY 5
B43: Management
B44: CTO
B45: Technology
B46: Marketing expenses
B47: Finance
B48: HR
...

Sheet Revenue_Sales Assumptions
B1: Name of Company
B2: REVENUE
C3: FY 2023 | D3: FY 2024 | E3: FY1 | F3: FY2 | G3: FY3 | H3: FY4 | I3: FY5
A4: A | B4: Product 1 | C4: 10 | D4: 30 | E4: =D4*(1+E5) -> 90 | F4: =E4*(1+F5) -> 270 | G4: =F4*(1+G5) -> 405 | H4: =G4*(1+H5) -> 607.5 | I4: =H4*(1+I5) -> 759.375
D5: =D4/C4-1 -> 2 | E5: =D5 -> 2 | F5: =E5 -> 2 | G5: 0.5 | H5: =G5 -> 0.5 | I5: 0.25
B6: Product 2 | C6: 20 | D6: 20 | E6: =D6*(1+E7) -> 24 | F6: =E6*(1+F7) -> 26.4 | G6: =F6*(1+G7) -> 29.04 | H6: =G6*(1+H7) -> 31.944 | I6: =H6*(1+I7) -> 35.1384
D7: =D6/C6-1 -> 0 | E7: 0.2 | F7: =10% -> 0.1 | G7: =10% -> 0.1 | H7: =10% -> 0.1 | I7: =10% -> 0.1 | J7: Change as per your business standard
B8: Product 3 | C8: 5 | D8: 50 | E8: =D8*(1+E9) -> 70 | F8: =E8*(1+F9) -> 98 | G8: =F8*(1+G9) -> 137.2 | H8: =G8*(1+H9) -> 164.64 | I8: =H8*(1+I9) -> 197.568
D9: =D8/C8-1 -> 9 | E9: 0.4 | F9: 0.4 | G9: 0.4 | H9: 0.2 | I9: 0.2 | J9: Change as per your business standard
B10: Product 4 | C10: 4 | D10: 10 | E10: =D10*(1+E11) -> 15 | F10: =E10*(1+F11) -> 22.5 | G10: =F10*(1+G11) -> 28.125 | H10: =G10*(1+H11) -> 30.9375 | I10: =H10*(1+I11) -> 34.03125
D11: =D10/C10-1 -> 1.5 | E11: 0.5 | F11: 0.5 | G11: 0.25 | H11: 0.1 | I11: 0.1 | J11: Change as per your business standard
B12: TOTAL Revenue | C12: =SUM(C6:C11) -> 29 | D12: =SUM(D6:D11) -> 90.5 | E12: =SUM(E6:E11) -> 110.1 | F12: =SUM(F6:F11) -> 147.9 | G12: =SUM(G6:G11) -> 195.115 | H12: =SUM(H6:H11) -> 227.9215 | I12: =SUM(I6:I11) -> 267.13765
E13: =E12/D12 -> 1.2165746 | F13: =F12/E12 -> 1.3433243 | G13: =G12/F12 -> 1.319236 | H13: =H12/G12 -> 1.1681393 | I13: =I12/H12 -> 1.1720599
B15: No of Customers
B16: New Additions during the period | C16: Nos
B17: Total | C17: Nos
B19: Geographic Spread (Active Customers)
B20: Rajasthan | C20: Nos | D20: 23 | E20: =$E$15*'Revenue_Sales Assumptions'!E28 -> 0 | F20: =$F$15*'Revenue_Sales Assumptions'!F28 -> 0 | G20: =$G$15*'Revenue_Sales Assumptions'!G28 -> 0 | H20: =$H$15*'Revenue_Sales Assumptions'!H28 -> 0 | I20: =$I$15*'Revenue_Sales Assumptions'!I28 -> 0
B21: Haryana | C21: Nos | D21: 24 | E21: =$E$15*'Revenue_Sales Assumptions'!E29 -> 0 | F21: =$F$15*'Revenue_Sales Assumptions'!F29 -> 0 | G21: =$G$15*'Revenue_Sales Assumptions'!G29 -> 0 | H21: =$H$15*'Revenue_Sales Assumptions'!H29 -> 0 | I21: =$I$15*'Revenue_Sales Assumptions'!I29 -> 0
B22: Madhya Pradesh | C22: Nos | D22: 0 | E22: =$E$15*'Revenue_Sales Assumptions'!E30 -> 0 | F22: =$F$15*'Revenue_Sales Assumptions'!F30 -> 0 | G22: =$G$15*'Revenue_Sales Assumptions'!G30 -> 0 | H22: =$H$15*'Revenue_Sales Assumptions'!H30 -> 0 | I22: =$I$15*'Revenue_Sales Assumptions'!I30 -> 0
B23: Uttar Pradesh | C23: Nos | D23: 0 | E23: =$E$15*'Revenue_Sales Assumptions'!E31 -> 0 | F23: =$F$15*'Revenue_Sales Assumptions'!F31 -> 0 | G23: =$G$15*'Revenue_Sales Assumptions'!G31 -> 0 | H23: =$H$15*'Revenue_Sales Assumptions'!H31 -> 0 | I23: =$I$15*'Revenue_Sales Assumptions'!I31 -> 0
B24: Punjab | C24: Nos | D24: 0 | E24: =$E$15*'Revenue_Sales Assumptions'!E32 -> 0 | F24: =$F$15*'Revenue_Sales Assumptions'!F32 -> 0 | G24: =$G$15*'Revenue_Sales Assumptions'!G32 -> 0 | H24: =$H$15*'Revenue_Sales Assumptions'!H32 -> 0 | I24: =$I$15*'Revenue_Sales Assumptions'!I32 -> 0
B25: Total | C25: Nos | D25: =SUM(D20:D24) -> 47 | E25: =SUM(E20:E24) -> 0 | F25: =SUM(F20:F24) -> 0 | G25: =SUM(G20:G24) -> 0 | H25: =SUM(H20:H24) -> 0 | I25: =SUM(I20:I24) -> 0
B27: Geographic Spread (in % terms)
B28: Rajasthan
B29: Haryana
B30: Madhya Pradesh
B31: Uttar Pradesh
B32: Punjab
B33: Total | E33: =SUM(E28:E32) -> 0 | F33: =SUM(F28:F32) -> 0 | G33: =SUM(G28:G32) -> 0 | H33: =SUM(H28:H32) -> 0 | I33: =SUM(I28:I32) -> 0
B36: Sales - Productwise (Quantity)
B37: Product 1 | C37: Nos
B38: Product 2 | C38: Nos
B39: Product 3 | C39: Nos
B40: Product 4 | C40: Nos
B41: New Product
B42: Total No of Transaction | C42: Nos | E42: =SUM(E37:E40) -> 0 | F42: =SUM(F37:F40) -> 0 | G42: =SUM(G37:G40) -> 0 | H42: =SUM(H37:H40) -> 0 | I42: =SUM(I37:I40) -> 0
B44: Sales Breakdown
B45: Product 1
B46: Product 2
...

Sheet Profit&Loss
A1: Name of Company
B2: FY2024 | C2: FY1 | D2: FY2 | E2: FY3 | F2: FY4 | G2: FY5
A3: Revenue
A4: Revenue | B4: ='Revenue_Sales Assumptions'!D12 -> 90.5 | C4: ='Revenue_Sales Assumptions'!E12 -> 110.1 | D4: ='Revenue_Sales Assumptions'!F12 -> 147.9 | E4: ='Revenue_Sales Assumptions'!G12 -> 195.115 | F4: ='Revenue_Sales Assumptions'!H12 -> 227.9215 | G4: ='Revenue_Sales Assumptions'!I12 -> 267.13765
A5: Other Income
A6: Total Revenue | B6: =B4+B5 -> 90.5 | C6: =C4+C5 -> 110.1 | D6: =D4+D5 -> 147.9 | E6: =E4+E5 -> 195.115 | F6: =F4+F5 -> 227.9215 | G6: =G4+G5 -> 267.13765
A7: Expenses
A8: Direct Expenses
A9: Manufacturing Costs
A10: Direct labour
A11: Factory expenses
A12: Total Direct Cost | B12: =SUM(B9:B11) -> 0 | C12: =SUM(C9:C11) -> 0 | D12: =SUM(D9:D11) -> 0 | E12: =SUM(E9:E11) -> 0 | F12: =SUM(F9:F11) -> 0 | G12: =SUM(G9:G11) -> 0
A13: Opening Inventory
A14: Closing Inventory | C14: =WC!D4 -> 0 | D14: =WC!E4 -> 0 | E14: =WC!F4 -> 0 | F14: =WC!G4 -> 0 | G14: =WC!H4 -> 0
A15: COGS | B15: =B13+B12-B14 -> 0 | C15: =C13+C12-C14 -> 0 | D15: =D13+D12-D14 -> 0 | E15: =E13+E12-E14 -> 0 | F15: =F13+F12-F14 -> 0 | G15: =G13+G12-G14 -> 0
A16: Gross Margin | B16: =B6-B15 -> 90.5 | C16: =C6-C15 -> 110.1 | D16: =D6-D15 -> 147.9 | E16: =E6-E15 -> 195.115 | F16: =F6-F15 -> 227.9215 | G16: =G6-G15 -> 267.13765
A17: Gross Margin (%) | B17: =B16/B6 -> 1 | C17: =C16/C6 -> 1 | D17: =D16/D6 -> 1 | E17: =E16/E6 -> 1 | F17: =F16/F6 -> 1 | G17: =G16/G6 -> 1
A18: Indirect Expenses
A19: Warehouse Rent | B19: ='Assumption Sheet'!E19 -> 0 | C19: ='Assumption Sheet'!F19 -> 0 | D19: ='Assumption Sheet'!G19 -> 0 | E19: ='Assumption Sheet'!H19 -> 0 | F19: ='Assumption Sheet'!I19 -> 0 | G19: ='Assumption Sheet'!J19 -> 0
A20: Office rent | B20: ='Assumption Sheet'!E20 -> 0 | C20: ='Assumption Sheet'!F20 -> 0 | D20: ='Assumption Sheet'!G20 -> 0 | E20: ='Assumption Sheet'!H20 -> 0 | F20: ='Assumption Sheet'!I20 -> 0 | G20: ='Assumption Sheet'!J20 -> 0
A21: Utilities costs (Electricity, Communication) | B21: ='Assumption Sheet'!E21 -> 0 | C21: ='Assumption Sheet'!F21 -> 0 | D21: ='Assumption Sheet'!G21 -> 0 | E21: ='Assumption Sheet'!H21 -> 0 | F21: ='Assumption Sheet'!I21 -> 0 | G21: ='Assumption Sheet'!J21 -> 0
A22: Infrastructure costs (admin, maintenance etc) | B22: ='Assumption Sheet'!E22 -> 0 | C22: ='Assumption Sheet'!F22 -> 0 | D22: ='Assumption Sheet'!G22 -> 0 | E22: ='Assumption Sheet'!H22 -> 0 | F22: ='Assumption Sheet'!I22 -> 0 | G22: ='Assumption Sheet'!J22 -> 0
A23: Travel & Conveyance - Sales Team | B23: ='Assumption Sheet'!E23 -> 0 | C23: ='Assumption Sheet'!F23 -> 0 | D23: ='Assumption Sheet'!G23 -> 0 | E23: ='Assumption Sheet'!H23 -> 0 | F23: ='Assumption Sheet'!I23 -> 0 | G23: ='Assumption Sheet'!J23 -> 0
A24: Employee training & engagement | B24: ='Assumption Sheet'!E24 -> 0 | C24: ='Assumption Sheet'!F24 -> 0 | D24: ='Assumption Sheet'!G24 -> 0 | E24: ='Assumption Sheet'!H24 -> 0 | F24: ='Assumption Sheet'!I24 -> 0 | G24: ='Assumption Sheet'!J24 -> 0
A25: Printing & Stationery | B25: ='Assumption Sheet'!E25 -> 0 | C25: ='Assumption Sheet'!F25 -> 0 | D25: ='Assumption Sheet'!G25 -> 0 | E25: ='Assumption Sheet'!H25 -> 0 | F25: ='Assumption Sheet'!I25 -> 0 | G25: ='Assumption Sheet'!J25 -> 0
A26: Server & Hosting | B26: ='Assumption Sheet'!E26 -> 0 | C26: ='Assumption Sheet'!F26 -> 0 | D26: ='Assumption Sheet'!G26 -> 0 | E26: ='Assumption Sheet'!H26 -> 0 | F26: ='Assumption Sheet'!I26 -> 0 | G26: ='Assumption Sheet'!J26 -> 0
A27: Mis Cost | B27: ='Assumption Sheet'!E27 -> 0 | C27: =C4*'Assumption Sheet'!F27 -> 0.27525 | D27: =D4*'Assumption Sheet'!G27 -> 0.36975 | E27: =E4*'Assumption Sheet'!H27 -> 0.4877875 | F27: =F4*'Assumption Sheet'!I27 -> 0.56980375 | G27: =G4*'Assumption Sheet'!J27 -> 0.66784413
A28: Marketing Expenses | B28: ='Assumption Sheet'!E16 -> 0 | C28: ='Assumption Sheet'!F16 -> 0 | D28: ='Assumption Sheet'!G16 -> 0 | E28: ='Assumption Sheet'!H16 -> 0 | F28: ='Assumption Sheet'!I16 -> 0 | G28: ='Assumption Sheet'!J16 -> 0
A29: Manpower Costs | B29: ='Assumption Sheet'!E61 -> 0 | C29: ='Assumption Sheet'!F61 -> 0 | D29: ='Assumption Sheet'!G61 -> 0 | E29: ='Assumption Sheet'!H61 -> 0 | F29: ='Assumption Sheet'!I61 -> 0 | G29: ='Assumption Sheet'!J61 -> 0
A30: Total Indirect Expenses | B30: =SUM(B19:B29) -> 0 | C30: =SUM(C19:C29) -> 0.27525 | D30: =SUM(D19:D29) -> 0.36975 | E30: =SUM(E19:E29) -> 0.4877875 | F30: =SUM(F19:F29) -> 0.56980375 | G30: =SUM(G19:G29) -> 0.66784413
A31: EBITDA | B31: =B16-B30 -> 90.5 | C31: =C16-C30 -> 109.82475 | D31: =D16-D30 -> 147.53025 | E31: =E16-E30 -> 194.62721 | F31: =F16-F30 -> 227.3517 | G31: =G16-G30 -> 266.46981
A32: EBITDA (%) | B32: =B31/B6 -> 1 | C32: =C31/C6 -> 0.9975 | D32: =D31/D6 -> 0.9975 | E32: =E31/E6 -> 0.9975 | F32: =F31/F6 -> 0.9975 | G32: =G31/G6 -> 0.9975
A33: Depriciation & Amortization | B33: ='Depreciation Sch'!C16 -> 0 | C33: ='Depreciation Sch'!F16 -> 0 | D33: ='Depreciation Sch'!I16 -> 0 | E33: ='Depreciation Sch'!L16 -> 0 | F33: ='Depreciation Sch'!O16 -> 0 | G33: ='Depreciation Sch'!R16 -> 0
A34: EBIT | B34: =B31-B33 -> 90.5 | C34: =C31-C33 -> 109.82475 | D34: =D31-D33 -> 147.53025 | E34: =E31-E33 -> 194.62721 | F34: =F31-F33 -> 227.3517 | G34: =G31-G33 -> 266.46981
A35: EBIT (%) | B35: =B34/B6 -> 1 | C35: =C34/C6 -> 0.9975 | D35: =D34/D6 -> 0.9975 | E35: =E34/E6 -> 0.9975 | F35: =F34/F6 -> 0.9975 | G35: =G34/G6 -> 0.9975
A36: Interest | B36: ='Loans Breakdown'!B15 -> 0 | C36: ='Loans Breakdown'!C15 -> 0 | D36: ='Loans Breakdown'!D15 -> 0 | E36: ='Loans Breakdown'!E15 -> 0 | F36: ='Loans Breakdown'!F15 -> 0 | G36: ='Loans Breakdown'!G15 -> 0
A37: EBT | B37: =B34-B36 -> 90.5 | C37: =C34-C36 -> 109.82475 | D37: =D34-D36 -> 147.53025 | E37: =E34-E36 -> 194.62721 | F37: =F34-F36 -> 227.3517 | G37: =G34-G36 -> 266.46981
A38: EBT(%) | B38: =B37/B6 -> 1 | C38: =C37/C6 -> 0.9975 | D38: =D37/D6 -> 0.9975 | E38: =E37/E6 -> 0.9975 | F38: =F37/F6 -> 0.9975 | G38: =G37/G6 -> 0.9975
A39: Income Tax | B39: =B37*Val_DCF!$D$40 -> 23.53 | C39: =C37*Val_DCF!$D$40 -> 28.554435 | D39: =D37*Val_DCF!$D$40 -> 38.357865 | E39: =E37*Val_DCF!$D$40 -> 50.603075 | F39: =F37*Val_DCF!$D$40 -> 59.111441 | G39: =G37*Val_DCF!$D$40 -> 69.28215
A40: PAT | B40: =B37-B39 -> 66.97 | C40: =C37-C39 -> 81.270315 | D40: =D37-D39 -> 109.17238 | E40: =E37-E39 -> 144.02414 | F40: =F37-F39 -> 168.24026 | G40: =G37-G39 -> 197.18766
...

Sheet Balance Sheet
B1: Name of Company | I1: Amount in INR
C3: FY 2023 | D3: FY 2024 | E3: FY 1 | F3: FY 2 | G3: FY 3 | H3: FY 4 | I3: FY 5
B4: EQUITY AND LIABILITIES
B5: Shareholder's funds: | D5: =SUM(D6:D7) -> 0 | E5: =SUM(E6:E7) -> 81.270315 | F5: =SUM(F6:F7) -> 190.4427 | G5: =SUM(G6:G7) -> 334.46684 | H5: =SUM(H6:H7) -> 502.70709 | I5: =SUM(I6:I7) -> 699.89475
B6: Equity Shareholders | E6: =D6+E45 -> 0 | F6: =E6+F45 -> 0 | G6: =F6+G45 -> 0 | H6: =G6+H45 -> 0 | I6: =H6+I45 -> 0
B7: Reserves and surplus | E7: =D7+'Profit&Loss'!C40 -> 81.270315 | F7: =E7+'Profit&Loss'!D40 -> 190.4427 | G7: =F7+'Profit&Loss'!E40 -> 334.46684 | H7: =G7+'Profit&Loss'!F40 -> 502.70709 | I7: =H7+'Profit&Loss'!G40 -> 699.89475
B8: Share application money pending for allotment | D8: 0 | E8: 0 | F8: 0 | G8: 0 | H8: 0 | I8: 0
B9: Non - current liabilities: | D9: =SUM(D10:D13) -> 0 | E9: =SUM(E10:E13) -> 0 | F9: =SUM(F10:F13) -> 0 | G9: =SUM(G10:G13) -> 0 | H9: =SUM(H10:H13) -> 0 | I9: =SUM(I10:I13) -> 0
B10: Long - term borrowings | E10: ='Loans Breakdown'!B4+'Loans Breakdown'!B5+'Loans Breakdown'!B6 -> 0 | F10: ='Loans Breakdown'!C4+'Loans Breakdown'!C5+'Loans Breakdown'!C6 -> 0 | G10: ='Loans Breakdown'!D4+'Loans Breakdown'!D5+'Loans Breakdown'!D6 -> 0 | H10: ='Loans Breakdown'!E4+'Loans Breakdown'!E5+'Loans Breakdown'!E6 -> 0 | I10: ='Loans Breakdown'!F4+'Loans Breakdown'!F5+'Loans Breakdown'!F6 -> 0
B11: Deferred tax liabilities (Net)
B12: Other Long - term liabilities
B13: Long - term provisions
B14: Current liabilities | D14: =SUM(D15:D19) -> 0 | E14: =SUM(E15:E19) -> 0 | F14: =SUM(F15:F19) -> 0 | G14: =SUM(G15:G19) -> 0 | H14: =SUM(H15:H19) -> 0 | I14: =SUM(I15:I19) -> 0
B15: Short - term borrowings | E15: ='Loans Breakdown'!B7 -> 0 | F15: ='Loans Breakdown'!C7 -> 0 | G15: ='Loans Breakdown'!D7 -> 0 | H15: ='Loans Breakdown'!E7 -> 0 | I15: ='Loans Breakdown'!F7 -> 0
B16: Trade payables
B17: Income received in advance
B18: Other current liabilities
B19: Short - term provisions
B20: Total | D20: =D5+D8+D9+D14 -> 0 | E20: =E5+E8+E9+E14 -> 81.270315 | F20: =F5+F8+F9+F14 -> 190.4427 | G20: =G5+G8+G9+G14 -> 334.46684 | H20: =H5+H8+H9+H14 -> 502.70709 | I20: =I5+I8+I9+I14 -> 699.89475
B21: ASSETS
B22: Non - current assets:
B23: WDV | D23: ='Depreciation Sch'!C14 -> 0 | E23: ='Depreciation Sch'!G14 -> 0 | F23: ='Depreciation Sch'!J14 -> 0 | G23: ='Depreciation Sch'!M14 -> 0 | H23: ='Depreciation Sch'!P14 -> 0 | I23: ='Depreciation Sch'!S14 -> 0
B24: Capital work-in-progress
B25: Investments and Deposits
B26: Deferred tax assets (Net) | E26: =0 -> 0 | F26: =0 -> 0 | G26: =0 -> 0 | H26: =0 -> 0 | I26: =0 -> 0
B27: Long-term loans and advances
B28: Other non-current assets | E28: =0 -> 0 | F28: =0 -> 0 | G28: =0 -> 0 | H28: =0 -> 0 | I28: =0 -> 0
B29: Current assets: | D29: =SUM(D30:D35) -> 0 | E29: =SUM(E30:E35) -> 6.0328767 | F29: =SUM(F30:F35) -> 8.1041096 | G29: =SUM(G30:G35) -> 8.0184247 | H29: =SUM(H30:H35) -> 9.366637 | I29: =SUM(I30:I35) -> 10.97826
B30: Current investments
B31: Inventories | D31: =WC!C4 -> 0 | E31: =WC!D4 -> 0 | F31: =WC!E4 -> 0 | G31: =WC!F4 -> 0 | H31: =WC!G4 -> 0 | I31: =WC!H4 -> 0
B32: Trade receivables | D32: =WC!C5 -> 0 | E32: =WC!D5 -> 6.0328767 | F32: =WC!E5 -> 8.1041096 | G32: =WC!F5 -> 8.0184247 | H32: =WC!G5 -> 9.366637 | I32: =WC!H5 -> 10.97826
B33: Cash and cash equivalents | D33: =WC!C6 -> 0 | E33: =WC!D6 -> 0 | F33: =WC!E6 -> 0 | G33: =WC!F6 -> 0 | H33: =WC!G6 -> 0 | I33: =WC!H6 -> 0
B34: Short-term loans and advances
B35: Other current assets
B36: Total | D36: =D23+D27+D29+D24+D26+D28 -> 0 | E36: =E23+E27+E29+E24+E26+E28 -> 6.0328767 | F36: =F23+F27+F29+F24+F26+F28 -> 8.1041096 | G36: =G23+G27+G29+G24+G26+G28 -> 8.0184247 | H36: =H23+H27+H29+H24+H26+H28 -> 9.366637 | I36: =I23+I27+I29+I24+I26+I28 -> 10.97826
D38: =D20-D36 -> 0 | E38: =E20-E36 -> 75.237438 | F38: =F20-F36 -> 182.33859 | G38: =G20-G36 -> 326.44841 | H38: =H20-H36 -> 493.34046 | I38: =I20-I36 -> 688.91649
B40: Working Capital
B41: Current Assets | D41: =D29-D33 -> 0 | E41: =E29-E33 -> 6.0328767 | F41: =F29-F33 -> 8.1041096 | G41: =G29-G33 -> 8.0184247 | H41: =H29-H33 -> 9.366637 | I41: =I29-I33 -> 10.97826
B42: Current Laibilities | D42: =D14 -> 0 | E42: =E17 -> 0 | F42: =F17 -> 0 | G42: =G17 -> 0 | H42: =H17 -> 0 | I42: =I17 -> 0
D43: =D41-D42 -> 0 | E43: =E41-E42 -> 6.0328767 | F43: =F41-F42 -> 8.1041096 | G43: =G41-G42 -> 8.0184247 | H43: =H41-H42 -> 9.366637 | I43: =I41-I42 -> 10.97826
...

Sheet CFS
A1: COMPANY NAME | G1: Amount in INR
A3: Cash flow statement
A5: Cash flow | B5: FY 2024 | C5: FY 1 | D5: FY 2 | E5: FY 3 | F5: FY 4 | G5: FY 5
A6: PAT | B6: ='Profit&Loss'!B40 -> 66.97 | C6: ='Profit&Loss'!C40 -> 81.270315 | D6: ='Profit&Loss'!D40 -> 109.17238 | E6: ='Profit&Loss'!E40 -> 144.02414 | F6: ='Profit&Loss'!F40 -> 168.24026 | G6: ='Profit&Loss'!G40 -> 197.18766
A7: Add: Depreciation | B7: ='Profit&Loss'!B33 -> 0 | C7: ='Profit&Loss'!C33 -> 0 | D7: ='Profit&Loss'!D33 -> 0 | E7: ='Profit&Loss'!E33 -> 0 | F7: ='Profit&Loss'!F33 -> 0 | G7: ='Profit&Loss'!G33 -> 0
A8: Add: Amortisations | D8: 0 | E8: 0 | F8: 0 | G8: 0
A9: Total cash accrual | C9: =+C6+B7+C8 -> 81.270315 | D9: =+D6+D7+D8 -> 109.17238 | E9: =+E6+E7+E8 -> 144.02414 | F9: =+F6+F7+F8 -> 168.24026 | G9: =+G6+G7+G8 -> 197.18766
A10: Changes in WC
A11: (Increase) /decrease in debtors | C11: ='Balance Sheet'!D32-'Balance Sheet'!E32 -> -6.0328767 | D11: ='Balance Sheet'!E32-'Balance Sheet'!F32 -> -2.0712329 | E11: ='Balance Sheet'!F32-'Balance Sheet'!G32 -> 0.085684932 | F11: ='Balance Sheet'!G32-'Balance Sheet'!H32 -> -1.3482123 | G11: ='Balance Sheet'!H32-'Balance Sheet'!I32 -> -1.6116226
A12: (Increase) /decrease in inventories | C12: ='Balance Sheet'!D31-'Balance Sheet'!E31 -> 0 | D12: ='Balance Sheet'!E31-'Balance Sheet'!F31 -> 0 | E12: ='Balance Sheet'!F31-'Balance Sheet'!G31 -> 0 | F12: ='Balance Sheet'!G31-'Balance Sheet'!H31 -> 0 | G12: ='Balance Sheet'!H31-'Balance Sheet'!I31 -> 0
A13: (Increase) /decrease in other Assets | C13: ='Balance Sheet'!D35-'Balance Sheet'!E35 -> 0 | D13: ='Balance Sheet'!E35-'Balance Sheet'!F35 -> 0 | E13: ='Balance Sheet'!F35-'Balance Sheet'!G35 -> 0 | F13: ='Balance Sheet'!G35-'Balance Sheet'!H35 -> 0 | G13: ='Balance Sheet'!H35-'Balance Sheet'!I35 -> 0
A14: Increase/(decrease) in Current Liabilities | C14: ='Balance Sheet'!E14-'Balance Sheet'!D14 -> 0 | D14: ='Balance Sheet'!F14-'Balance Sheet'!E14 -> 0 | E14: ='Balance Sheet'!G14-'Balance Sheet'!F14 -> 0 | F14: ='Balance Sheet'!H14-'Balance Sheet'!G14 -> 0 | G14: ='Balance Sheet'!I14-'Balance Sheet'!H14 -> 0
A15: Total cash flow from Operations after WC changes | C15: =+SUM(C9:C14) -> 75.237438 | D15: =+SUM(D9:D14) -> 107.10115 | E15: =+SUM(E9:E14) -> 144.10982 | F15: =+SUM(F9:F14) -> 166.89204 | G15: =+SUM(G9:G14) -> 195.57603
A16: Changes in investing activities
A17: (Purchase) of FA | C17: ='Depreciation Sch'!E14 -> 0 | D17: ='Depreciation Sch'!H14 -> 0 | E17: ='Depreciation Sch'!K14 -> 0 | F17: ='Depreciation Sch'!N14 -> 0 | G17: ='Depreciation Sch'!Q14 -> 0
A18: (Purchase)/Sale of Investments
A19: Total cash flow after investing activities | C19: =+SUM(C15:C18) -> 75.237438 | D19: =+SUM(D15:D18) -> 107.10115 | E19: =+SUM(E15:E18) -> 144.10982 | F19: =+SUM(F15:F18) -> 166.89204 | G19: =+SUM(G15:G18) -> 195.57603
A20: Changes in financing activities
A21: Equity infusion | C21: ='Balance Sheet'!E6-'Balance Sheet'!D6 -> 0 | D21: ='Balance Sheet'!F6-'Balance Sheet'!E6 -> 0 | E21: ='Balance Sheet'!G6-'Balance Sheet'!F6 -> 0 | F21: ='Balance Sheet'!H6-'Balance Sheet'!G6 -> 0 | G21: ='Balance Sheet'!I6-'Balance Sheet'!H6 -> 0
A22: Debt infusion
A23: Total changes after financing activities | C23: =+SUM(C19:C22) -> 75.237438 | D23: =+SUM(D19:D22) -> 107.10115 | E23: =+SUM(E19:E22) -> 144.10982 | F23: =+SUM(F19:F22) -> 166.89204 | G23: =+SUM(G19:G22) -> 195.57603
A24: Opening cash balance | C24: =B25 -> 0 | D24: =C25 -> 75.237438 | E24: =D25 -> 182.33859 | F24: =E25 -> 326.44841 | G24: =F25 -> 493.34046
A25: Closing cash balance | C25: =C23+C24 -> 75.237438 | D25: =D23+D24 -> 182.33859 | E25: =E23+E24 -> 326.44841 | F25: =F23+F24 -> 493.34046 | G25: =G23+G24 -> 688.91649
A26: Check | C26: =+C24+C23-C25 -> 0 | D26: =+D24+D23-D25 -> 0 | E26: =+E24+E23-E25 -> 0 | F26: =+F24+F23-F25 -> 0 | G26: =+G24+G23-G25 -> 0

Sheet WC
B1: Name of Company
A3: 1 | B3: Working Capital | C3: FY 24 | D3: FY 1 | E3: FY 2 | F3: FY 3 | G3: FY 4 | H3: FY 5
B4: Inventory | D4: =('Assumption Sheet'!F66*'Profit&Loss'!C9)/365 -> 0 | E4: =('Assumption Sheet'!G66*'Profit&Loss'!D9)/365 -> 0 | F4: =('Assumption Sheet'!H66*'Profit&Loss'!E9)/365 -> 0 | G4: =('Assumption Sheet'!I66*'Profit&Loss'!F9)/365 -> 0 | H4: =('Assumption Sheet'!J66*'Profit&Loss'!G9)/365 -> 0
B5: Trade Receivables | D5: =('Profit&Loss'!C4*'Assumption Sheet'!F67)/365 -> 6.0328767 | E5: =('Profit&Loss'!D4*'Assumption Sheet'!G67)/365 -> 8.1041096 | F5: =('Profit&Loss'!E4*'Assumption Sheet'!H67)/365 -> 8.0184247 | G5: =('Profit&Loss'!F4*'Assumption Sheet'!I67)/365 -> 9.366637 | H5: =('Profit&Loss'!G4*'Assumption Sheet'!J67)/365 -> 10.97826
B6: Trade Payables | D6: =('Assumption Sheet'!F68*'Profit&Loss'!C9)/365 -> 0 | E6: =('Assumption Sheet'!G68*'Profit&Loss'!D9)/365 -> 0 | F6: =('Assumption Sheet'!H68*'Profit&Loss'!E9)/365 -> 0 | G6: =('Assumption Sheet'!I68*'Profit&Loss'!F9)/365 -> 0 | H6: =('Assumption Sheet'!J68*'Profit&Loss'!G9)/365 -> 0

Sheet Depreciation Sch
B1: Company Name
B3: Fixed Asset Register
B4: INR Millions | C4: Net Book Value as at 01 Apr 24 | D4: Useful life (years) | E4: Additions | F4: Depreciation during FY1 | G4: NBV as at FY 1 | H4: Additions | I4: Depreciation during FY2 | J4: NBV as at FY 2 | K4: Additions | L4: Depreciation during FY3 | M4: NBV as at FY 3 | N4: Additions | O4: Depreciation during FY4 | P4: NBV as at FY 4 | Q4: Additions | R4: Depreciation during FY5 | S4: NBV as at FY 5
B5: Furniture & Fixtures | C5: 0 | D5: 5 | E5: ='Assumption Sheet'!F74 -> 0 | F5: =SUM(C5,E5)/D5 -> 0 | H5: ='Assumption Sheet'!G74/1000000 -> 0 | I5: =SUM(G5:H5)/D5 -> 0 | J5: =G5+H5-I5 -> 0 | K5: =('Assumption Sheet'!H74)/1000000 -> 0 | L5: =SUM(J5:K5)/D5 -> 0 | M5: =J5+K5-L5 -> 0 | N5: =('Assumption Sheet'!I74)/1000000 -> 0 | O5: =SUM(M5:N5)/D5 -> 0 | P5: =M5+N5-O5 -> 0 | Q5: =('Assumption Sheet'!J74)/1000000 -> 0 | R5: =SUM(P5:Q5)/D5 -> 0 | S5: =P5+Q5-R5 -> 0
B6: Computers & Servers | C6: 0 | D6: 5 | E6: ='Assumption Sheet'!G75 -> 0 | F6: =SUM(C6,E6)/D6 -> 0 | G6: =C6+E6-F6 -> 0 | H6: ='Assumption Sheet'!G75/1000000 -> 0 | I6: =SUM(G6:H6)/D6 -> 0 | J6: =G6+H6-I6 -> 0 | K6: =('Assumption Sheet'!H75)/1000000 -> 0 | L6: =SUM(J6:K6)/D6 -> 0 | M6: =J6+K6-L6 -> 0 | N6: =('Assumption Sheet'!I75)/1000000 -> 0 | O6: =SUM(M6:N6)/D6 -> 0 | P6: =M6+N6-O6 -> 0 | Q6: =('Assumption Sheet'!J75)/1000000 -> 0 | R6: =SUM(P6:Q6)/D6 -> 0 | S6: =P6+Q6-R6 -> 0
B7: Office Equipments | C7: 0 | D7: 5 | E7: =SUM('Assumption Sheet'!F76:F77) -> 0 | F7: =SUM(C7,E7)/D7 -> 0 | G7: =C7+E7-F7 -> 0 | H7: =SUM('Assumption Sheet'!G76:G77)/1000000 -> 0 | I7: =SUM(G7:H7)/D7 -> 0 | J7: =G7+H7-I7 -> 0 | K7: =(SUM('Assumption Sheet'!H76:H77))/1000000 -> 0 | L7: =SUM(J7:K7)/D7 -> 0 | M7: =J7+K7-L7 -> 0 | N7: =(SUM('Assumption Sheet'!I76:I77))/1000000 -> 0 | O7: =SUM(M7:N7)/D7 -> 0 | P7: =M7+N7-O7 -> 0 | Q7: =(SUM('Assumption Sheet'!J76:J77))/1000000 -> 0 | R7: =SUM(P7:Q7)/D7 -> 0 | S7: =P7+Q7-R7 -> 0
B8: Vehicle | C8: 0 | D8: 5 | E8: ='Assumption Sheet'!F80 -> 0 | F8: =SUM(C8,E8)/D8 -> 0 | G8: =C8+E8-F8 -> 0 | H8: ='Assumption Sheet'!G80/1000000 -> 0 | I8: =SUM(G8:H8)/D8 -> 0 | J8: =G8+H8-I8 -> 0 | K8: =('Assumption Sheet'!H80)/1000000 -> 0 | L8: =SUM(J8:K8)/D8 -> 0 | M8: =J8+K8-L8 -> 0 | N8: =('Assumption Sheet'!I80)/1000000 -> 0 | O8: =SUM(M8:N8)/D8 -> 0 | P8: =M8+N8-O8 -> 0 | Q8: =('Assumption Sheet'!J80)/1000000 -> 0 | R8: =SUM(P8:Q8)/D8 -> 0 | S8: =P8+Q8-R8 -> 0
B9: Tangible Assets | C9: =SUM(C6:C7) -> 0 | E9: =SUM(E5:E8) -> 0 | F9: =SUM(F5:F8) -> 0 | G9: =SUM(G5:G8) -> 0 | H9: =SUM(H5:H8) -> 0 | I9: =SUM(I5:I8) -> 0 | J9: =SUM(J5:J8) -> 0 | K9: =SUM(K5:K8) -> 0 | L9: =SUM(L5:L8) -> 0 | ... S9: =SUM(S5:S8) -> 0
B11: License Software | C11: ='Balance Sheet'!F6 -> 0 | D11: 5 | E11: ='Assumption Sheet'!F78 -> 0 | F11: =SUM(C11,E11)/D11 -> 0 | G11: =C11+E11-F11 -> 0 | H11: ='Assumption Sheet'!G78/1000000 -> 0 | I11: =SUM(G11:H11)/D11 -> 0 | J11: =G11+H11-I11 -> 0 | K11: =('Assumption Sheet'!H78)/1000000 -> 0 | L11: =SUM(J11:K11)/D11 -> 0 | M11: =J11+K11-L11 -> 0 | N11: =('Assumption Sheet'!I78)/1000000 -> 0 | O11: =SUM(M11:N11)/D11 -> 0 | P11: =M11+N11-O11 -> 0 | Q11: =('Assumption Sheet'!J78)/1000000 -> 0 | R11: =SUM(P11:Q11)/D11 -> 0 | S11: =P11+Q11-R11 -> 0
B12: Inhouse CRM development | C12: 0 | D12: 10 | E12: ='Assumption Sheet'!F79 -> 0 | F12: =SUM(C12,E12)/D12 -> 0 | G12: =C12+E12-F12 -> 0 | H12: ='Assumption Sheet'!G79/1000000 -> 0 | I12: =SUM(G12:H12)/D12 -> 0 | J12: =G12+H12-I12 -> 0 | K12: =('Assumption Sheet'!H79)/1000000 -> 0 | L12: =SUM(J12:K12)/D12 -> 0 | M12: =J12+K12-L12 -> 0 | N12: =('Assumption Sheet'!I79)/1000000 -> 0 | O12: =SUM(M12:N12)/D12 -> 0 | P12: =M12+N12-O12 -> 0 | Q12: =('Assumption Sheet'!J79)/1000000 -> 0 | R12: =SUM(P12:Q12)/D12 -> 0 | S12: =P12+Q12-R12 -> 0
B13: Intangible Assets | E13: =SUM(E11:E12) -> 0 | F13: =SUM(F11:F12) -> 0 | G13: =SUM(G11:G12) -> 0 | H13: =SUM(H11:H12) -> 0 | I13: =SUM(I11:I12) -> 0 | J13: =SUM(J11:J12) -> 0 | K13: =SUM(K11:K12) -> 0 | L13: =SUM(L11:L12) -> 0 | ... S13: =SUM(S11:S12) -> 0
B14: Total | C14: =C9+C12 -> 0 | E14: =E9+E13 -> 0 | F14: =F9+F13 -> 0 | G14: =G9+G13 -> 0 | H14: =H9+H13 -> 0 | I14: =I9+I13 -> 0 | J14: =J9+J13 -> 0 | K14: =K9+K13 -> 0 | L14: =L9+L13 -> 0 | ... S14: =S9+S13 -> 0
B16: Total Depreciation | C16: =C14 -> 0 | D16: 0 | F16: =F14 -> 0 | G16: 0 | H16: 0 | I16: =I14 -> 0 | J16: 0 | L16: =L14 -> 0 | M16: 0 | O16: =O14 -> 0 | P16: 0 | R16: =R14 -> 0 | S16: 0
B17: Addition during the year | D17: =D14 -> 0 | E17: =E14 -> 0 | F17: 0 | G17: 0 | H17: =H14 -> 0 | I17: 0 | J17: 0 | K17: =K14 -> 0 | L17: 0 | M17: 0 | N17: =N14 -> 0 | O17: 0 | P17: 0 | Q17: =Q14 -> 0 | R17: 0 | S17: 0
B18: Net Book Value | C18: 0 | D18: 0 | F18: 0 | G18: =G14 -> 0 | H18: 0 | I18: 0 | J18: =J14 -> 0 | L18: 0 | M18: =M14 -> 0 | O18: 0 | P18: =P14 -> 0 | R18: 0 | S18: =S14 -> 0

Sheet Loans Breakdown
A2: Loan Details
A3: Loans | B3: 1 | C3: 2 | D3: 3 | E3: 4 | F3: 5
A4: Loan 1 | B4: 0 | C4: 0 | D4: 0 | E4: 0 | F4: 0
A5: Loan 2 | B5: 0 | C5: 0 | D5: 0 | E5: 0 | F5: 0
A6: Vehicle Loans | B6: 0 | C6: 0 | D6: 0 | E6: 0 | F6: 0
A7: Working Capital Loan
A8: Total | B8: =SUM(B4:B6) -> 0 | C8: =SUM(C4:C6) -> 0 | D8: =SUM(D4:D5) -> 0 | E8: =SUM(E4:E5) -> 0 | F8: =SUM(F4:F5) -> 0
A10: Interest
A11: Loan 1
A12: Loan 2
A13: Vehicle Loan
A14: Working Capital Loan | B14: =B60 -> 0 | C14: =C60 -> 0 | D14: =D60 -> 0 | E14: =E60 -> 0 | F14: =F60 -> 0
A15: Total | B15: =SUM(B11:B13) -> 0 | C15: =SUM(C11:C13) -> 0 | D15: =SUM(D11:D13) -> 0 | E15: =SUM(E11:E13) -> 0 | F15: =SUM(F11:F13) -> 0
A17: Loan 1
A18: Loan Amount
A19: Date of Disbursement - INR __________ lacs
A20: Particulars | B20: Interest | C20: Principal | D20: Total | E20: Balance
A21: D+6 | D21: =B21+C21 -> 0 | E21: =B18-C21 -> 0
A22: D+12 | D22: =B22+C22 -> 0 | E22: =E21-C22 -> 0
A23: D+18 | D23: =B23+C23 -> 0 | E23: =E22-C23 -> 0
A24: D+24 | D24: =B24+C24 -> 0 | E24: =E23-C24 -> 0
A25: D+30 | D25: =B25+C25 -> 0 | E25: =E24-C25 -> 0
A26: D+36 | D26: =B26+C26 -> 0 | E26: =E25-C26 -> 0
A27: Sub-total (A) | B27: =SUM(B21:B26) -> 0 | C27: =SUM(C21:C26) -> 0 | D27: =SUM(D21:D26) -> 0
A29: Loan 2
A30: Loan Amount
A31: Date of Disbursement - INR __________ lacs
A32: Particulars | B32: Interest | C32: Principal | D32: Total | E32: Balance
A33: D+6 | D33: =B33+C33 -> 0 | E33: =B30-C33 -> 0
A34: D+12 | D34: =B34+C34 -> 0 | E34: =E33-C34 -> 0
A35: D+18 | D35: =B35+C35 -> 0 | E35: =E34-C35 -> 0
A36: D+24 | D36: =B36+C36 -> 0 | E36: =E35-C36 -> 0
A37: D+30 | D37: =B37+C37 -> 0 | E37: =E36-C37 -> 0
A38: D+36 | D38: =B38+C38 -> 0 | E38: =E37-C38 -> 0
A39: Sub-total (B) | B39: =SUM(B33:B38) -> 0 | C39: =SUM(C33:C38) -> 0
A40: A+B | B40: =B27+B39 -> 0 | C40: =C27+C39 -> 0
A42: Vehicle Loan
A43: Loan Amount
A44: Date of Disbursement - INR __________ lacs
A45: Particulars | B45: Interest | C45: Principal | D45: Total | E45: Balance
...

Sheet Historical P&L
B1: FreshoKartz Agri products Pvt Ltd
B3: Historical Profit & Loss
B4: INR crores | C4: FY18 | D4: FY19 | E4: FY20
B5: Revenue from Operations | C5: 2.28 | D5: 3.72 | E5: 5.1389261
B6: Purchases | C6: =(-21771880+462920)/10000000 -> -2.130896 | D6: -3.1033285 | E6: -3.95
B7: Freight expenses and Other costs | C7: -0.1347509 | D7: -0.5228354 | E7: -0.95
B8: Gross Margin | C8: =SUM(C5:C7) -> 0.0143531 | D8: =SUM(D5:D7) -> 0.0938361 | E8: =SUM(E5:E7) -> 0.2389261
B9: Employee Costs | C9: -0.1770003 | D9: -0.2815643 | E9: -0.35
B10: Marketing & Promotion Expenses | C10: 0 | D10: -0.015 | E10: -0.02
B11: Other Expenses | C11: =-442029/10000000 -> -0.0442029 | D11: -0.3660948 | E11: -0.25
B12: EBITDA | C12: =SUM(C8:C11) -> -0.2068501 | D12: =SUM(D8:D11) -> -0.568823 | E12: =SUM(E8:E11) -> -0.3810739
B13: Depreciation | C13: -0.0034074 | D13: -0.002 | E13: -0.0089
B14: EBIT | C14: =C12+C13 -> -0.2102575 | D14: =D12+D13 -> -0.570823 | E14: =E12+E13 -> -0.3899739
B15: Finance costs | C15: -0.0031814 | D15: =-64215/10000000 -> -0.0064215 | E15: -0.0122
B16: Net Loss | C16: =C14+C15 -> -0.2134389 | D16: =D14+D15 -> -0.5772445 | E16: =E14+E15 -> -0.4021739
B18: Revenue Growth % | C18: na | D18: =D5/C5-1 -> 0.63157895 | E18: =E5/D5-1 -> 0.38143175
B19: Gross Margin % | C19: =C8/C5 -> 0.0062952193 | D19: =D8/D5 -> 0.025224758 | E19: =E8/E5 -> 0.046493391
B20: EBITDA % | C20: =C12/C5 -> -0.090723728 | D20: =D12/D5 -> -0.15290941 | E20: =E12/E5 -> -0.074154384
B21: Employee costs % of revenue | C21: =-C9/C5 -> 0.077631711 | D21: =-D9/D5 -> 0.075689328 | E21: =-E9/E5 -> 0.068107615
F23: Avoid stand alone - integrate with P&L

Sheet Historical Metrics
B1: FreshoKartz Agri products Pvt Ltd | C1: Prachi - inlcud ethsi infrmation on the PL KPI tab
B3: Financial Metrics
B4: INR | C4: FY17-18 | D4: FY18-19 | E4: FY19-20 | F4: % of Total | G4: Q1FY21 | H4: % of Total | I4: Annualised Projected - FY21 | J4: % of Total
B5: Output Sales | C5: 22000000 | D5: 37200000 | E5: 46215939 | F5: =E5/E$7 -> 0.89565773 | G5: 8042363 | H5: =G5/G$7 -> 0.35200202 | I5: =G5/3*12 -> 32169452 | J5: =I5/I$7 -> 0.35200202
B6: Input Sales | C6: 0 | D6: 0 | E6: 5384061 | F6: =E6/E$7 -> 0.10434227 | G6: 14805128 | H6: =G6/G$7 -> 0.64799798 | I6: =G6/3*12 -> 59220512 | J6: =I6/I$7 -> 0.64799798
B7: Total | C7: =SUM(C5:C6) -> 22000000 | D7: =SUM(D5:D6) -> 37200000 | E7: =SUM(E5:E6) -> 51600000 | G7: =SUM(G5:G6) -> 22847491 | I7: =SUM(I5:I6) -> 91389964
B9: Output Sales KPIs
B10: No of farmers in Output (Nos) | C10: 502 | D10: 994 | E10: 1183 | F10: =E10/E30 -> 0.26728423 | G10: 205 | H10: =G10/G30 -> 0.051007713 | I10: =G10/3*12 -> 820 | J10: =I10/I30 -> 0.051007713
B11: No. of transactions (Nos) | C11: 7654 | D11: 11094 | E11: 6542 | F11: =E11/E31 -> 0.60624595 | G11: 87 | H11: =G11/G31 -> 0.015220434 | I11: =G11/3*12 -> 348 | J11: =I11/I31 -> 0.015220434
B12: Avg transaction per farmer (Rs) | C12: =C5/C10 -> 43824.701 | D12: =D5/D10 -> 37424.547 | E12: =E5/E10 -> 39066.728 | G12: =G5/G10 -> 39231.039 | I12: =I5/I10 -> 39231.039
B13: Avg transaction value (Rs) | C13: =C5/C11 -> 2874.3141 | D13: =D5/D11 -> 3353.1639 | E13: =E5/E11 -> 7064.4969 | G13: =G5/G11 -> 92440.954 | I13: =I5/I11 -> 92440.954
B16: Input Sales KPIs
B17: No of farmers in Input (Nos) | C17: 0 | D17: 0 | E17: 3243 | F17: =E17/E30 -> 0.73271577 | G17: 3814 | H17: =G17/G30 -> 0.94899229 | I17: =G17/3*12 -> 15256 | J17: =I17/I30 -> 0.94899229
B18: No. of transactions (Nos) | C18: 0 | D18: 0 | E18: 4249 | F18: =E18/E31 -> 0.39375405 | G18: 5629 | H18: =G18/G31 -> 0.98477957 | I18: =G18/3*12 -> 22516 | J18: =I18/I31 -> 0.98477957
B19: Avg transaction per farmer (Rs) | C19: 0 | D19: 0 | E19: =E6/E17 -> 1660.21 | G19: =G6/G17 -> 3881.785 | I19: =I6/I17 -> 3881.785
B20: Avg transaction value (Rs) | C20: 0 | D20: 0 | E20: =E6/E18 -> 1267.136 | G20: =G6/G18 -> 2630.1524 | I20: =I6/I18 -> 2630.1524
B21: Orders Per Farmers (Nos) | C21: 0 | D21: 0 | E21: =E18/E17 -> 1.3102066 | G21: =G18/G17 -> 1.4758783 | I21: =I18/I17 -> 1.4758783
B22: No of Repeated farmers * | C22: 0 | D22: 0 | E22: 400 | G22: 893 | I22: =I17*G23 -> 3572
B23: % of repeated farmers | C23: 0 | D23: 0 | E23: =E22/E17 -> 0.12334258 | G23: =G22/G17 -> 0.23413739 | I23: =I22/I17 -> 0.23413739
B24: No of active FK Centers | C24: 0 | D24: 0 | E24: 10 | G24: 26 | I24: 26
B25: Ratio of Input Sales
B26: Seeds | C26: 0 | D26: 0 | E26: na | G26: 5922051.2 | H26: =G26/($G$26+$G$27+$G$28) -> 0.4
B27: Fertilisers | C27: 0 | D27: 0 | E27: na | G27: 4441538.4 | H27: =G27/($G$26+$G$27+$G$28) -> 0.3
B28: Pesticides | C28: 0 | D28: 0 | E28: na | G28: 4441538.4 | H28: =G28/($G$26+$G$27+$G$28) -> 0.3
B30: Number of Farmers Total | E30: =E10+E17 -> 4426 | G30: =G10+G17 -> 4019 | I30: =I10+I17 -> 16076
B31: Number of Transactions Total | E31: =E11+E18 -> 10791 | G31: =G11+G18 -> 5716 | I31: =I11+I18 -> 22864
B32: Number of Transaction/Output Farmer | E32: =E11/E10 -> 5.5300085 | G32: =G11/G10 -> 0.42439024 | I32: 1.3
B33: Number of input transaction/ Inputt Farmer | E33: =E18/E17 -> 1.3102066 | G33: =G18/G17 -> 1.4758783 | I33: =I18/I17 -> 1.4758783
B34: Number Overall Transaction / Farmer | E34: =E31/E30 -> 2.4380931 | G34: =G31/G30 -> 1.4222443 | I34: =I31/I30 -> 1.4222443
B40: * Repeated farmers = Farmers transacted more than 1 time, there are 340 farmers who have transacted minimum 3 times. | I40: Avoid Stand alone - include with Metrics
B42: Note 1: 46 Crop Advisory has provide at INR 500 (INR 23,000)
B43: Note 2: 48 farmers of INR 10,000 per farmer has been provided Input Financing through Sagri (Japanese Agri Financing Co)
B45: na- Not Available

Sheet Valuation_Market Multiple
A1: Company Name
B2: PE/VC Transactions ($ in Millions)
B3: Company | C3: Date Raised | D3: AmountRaised | E3: Pre Money Equity | F3: Post Money Equity | G3: Dilution | H3: Revenue (TTM, Year of Funding) | I3: EBITDA | J3: PAT | K3: Pre Money Equity Valuation / Revenue (X) | L3: Total Funding to Date
K4: =E4/H4 -> #DIV/0!
K5: =E5/H5 -> #DIV/0!
K6: =E6/H6 -> #DIV/0!
K7: =E7/H7 -> #DIV/0!
K8: =E8/H8 -> #DIV/0!
K9: =E9/H9 -> #DIV/0!
K10: =E10/H10 -> #DIV/0!
K11: =AVERAGE(K4:K10) -> #DIV/0!
B13: M&A Transactions ($ in Millions) - NONE
B14: Company | C14: M&A year | D14: AmountRaised | E14: Pre Money Equity | F14: Post Money Equity | G14: Dilution | H14: Revenue | I14: EBITDA | J14: PAT | K14: Pre Money Equity Valuation / Revenue (X) | L14: Total Funding to Date
B15: Not Available / No Transactions noted
B17: Publicly Traded ($ in Million, other than per share values) - NONE
B18: Company Name | D18: TEV | E18: Market Cap | F18: Revenue | G18: EBITDA / EBITDA Margin | H18: PAT | I18: TEV / Revenue | J18: TEV/EBITDA | K18: Mkt Cap / Revenue | L18: Mkt Cap / EBITDA
B19: None noted
B21: Company Name
B22: Average Market Cap /Rev | K22: =K11 -> #DIV/0!
B23: Discount | K23: 0.5 | L23: This no to be applied based on the industry and relative company
B24: Pre Money Equity Valuation | K24: =K22*K23 -> #DIV/0!
B25: Pre Money Equity Valuation (Rs.) | K25: =K24*#REF! -> #DIV/0!

Sheet Val_DCF
A1: Company Name
B3: Discounted Cash Flow
B4: Valuation date
B5: Financial years ended March 31 | J5: In INR | L5: Old Numbers
E6: FY 2024 | F6: FY 1 | G6: FY 2 | H6: FY 3 | I6: FY 4 | J6: FY 5 | L6: 44286 | M6: 44651 | N6: 45016 | O6: 45382 | P6: 45747
B8: Revenue | E8: ='Profit&Loss'!B6 -> 90.5 | F8: ='Profit&Loss'!C6 -> 110.1 | G8: ='Profit&Loss'!D6 -> 147.9 | H8: ='Profit&Loss'!E6 -> 195.115 | I8: ='Profit&Loss'!F6 -> 227.9215 | J8: ='Profit&Loss'!G6 -> 267.13765 | L8: 133364125 | M8: 240868250 | N8: 390704250 | O8: 779649800 | P8: 1173523200
B9: Y-o-Y growth | E9: =E8/D8-1 -> #DIV/0! | F9: =F8/E8-1 -> 0.21657459 | G9: =G8/F8-1 -> 0.34332425 | H9: =H8/G8-1 -> 0.31923597 | I9: =I8/H8-1 -> 0.1681393 | J9: =J8/I8-1 -> 0.1720599 | L9: 0.6560396 | M9: 0.80609478 | N9: 0.62206621 | O9: 0.99549864 | P9: 0.50519272
B11: Net profit | E11: ='Profit&Loss'!B40 -> 66.97 | F11: ='Profit&Loss'!C40 -> 81.270315 | G11: ='Profit&Loss'!D40 -> 109.17238 | H11: ='Profit&Loss'!E40 -> 144.02414 | I11: ='Profit&Loss'!F40 -> 168.24026 | J11: ='Profit&Loss'!G40 -> 197.18766 | L11: 3678677.7 | M11: 5604631.1 | N11: 7328572 | O11: 88596761 | P11: 2.1791135e+08
B12: As % of revenue | E12: =E11/E8 -> 0.74 | F12: =F11/F8 -> 0.73815 | G12: =G11/G8 -> 0.73815 | H12: =H11/H8 -> 0.73815 | I12: =I11/I8 -> 0.73815 | J12: =J11/J8 -> 0.73815 | L12: 0.027583713 | M12: 0.023268451 | N12: 0.018757339 | O12: 0.11363661 | P12: 0.18568985
B14: Interest expense (tax adjusted) | E14: ='Profit&Loss'!B36*(1-$D$40) -> 0 | F14: ='Profit&Loss'!C36*(1-$D$40) -> 0 | G14: ='Profit&Loss'!D36*(1-$D$40) -> 0 | H14: ='Profit&Loss'!E36*(1-$D$40) -> 0 | I14: ='Profit&Loss'!F36*(1-$D$40) -> 0 | J14: ='Profit&Loss'!G36*(1-$D$40) -> 0 | L14: 2469949.8 | M14: 2651969.9 | N14: 5524990 | O14: 9828000 | P14: 11700000
B15: Adjusted Net Income | C15: =IFERROR(C11+C14,"n.a.") -> 0 | D15: =IFERROR(D11+D14,"n.a.") -> 0 | E15: =IFERROR(E11+E14,"n.a.") -> 66.97 | F15: =IFERROR(F11+F14,"n.a.") -> 81.270315 | G15: =IFERROR(G11+G14,"n.a.") -> 109.17238 | H15: =IFERROR(H11+H14,"n.a.") -> 144.02414 | I15: =IFERROR(I11+I14,"n.a.") -> 168.24026 | J15: =IFERROR(J11+J14,"n.a.") -> 197.18766 | L15: 6148627.5 | M15: 8256601 | N15: 12853562 | O15: 98424761 | P15: 2.2961135e+08
B17: Depreciation and Amortization | E17: ='Profit&Loss'!B33 -> 0 | F17: ='Profit&Loss'!C33 -> 0 | G17: ='Profit&Loss'!D33 -> 0 | H17: ='Profit&Loss'!E33 -> 0 | I17: ='Profit&Loss'!F33 -> 0 | J17: ='Profit&Loss'!G33 -> 0 | L17: 8935507.5 | M17: 22592258 | N17: 40916258 | O17: 67152008 | P17: 1.0234426e+08
B18: D&A as % of capex | D18: =+IFERROR(-D17/D22,"n.a.") -> n.a. | E18: =+IFERROR(-E17/E22,"n.a.") -> n.a. | F18: =+IFERROR(-F17/F22,"n.a.") -> n.a. | G18: =+IFERROR(-G17/G22,"n.a.") -> n.a. | H18: =+IFERROR(-H17/H22,"n.a.") -> n.a. | I18: =+IFERROR(-I17/I22,"n.a.") -> n.a. | J18: =+IFERROR(-J17/J22,"n.a.") -> n.a. | L18: 0.15494876 | M18: 0.2863404 | N18: 0.39214355 | O18: 0.42496564 | P18: 0.52780618
B19: Changes in working capital | D19: =('Balance Sheet'!E16-'Balance Sheet'!D16)*10^6 -> 0 | E19: =-('Balance Sheet'!F16-'Balance Sheet'!E16)*10^6 -> 0 | F19: =-('Balance Sheet'!G16-'Balance Sheet'!F16)*10^6 -> 0 | G19: =-('Balance Sheet'!H16-'Balance Sheet'!G16)*10^6 -> 0 | H19: =-('Balance Sheet'!I16-'Balance Sheet'!H16)*10^6 -> 0 | I19: =-('Balance Sheet'!J16-'Balance Sheet'!I16)*10^6 -> 0 | J19: =-('Balance Sheet'!K16-'Balance Sheet'!J16)*10^6 -> 0 | L19: 6081030.9 | M19: 1487498.2 | N19: -969432.25 | O19: -37390914 | P19: -45549235
B20: As % of incremental revenue | D20: =IFERROR(-D19/(D8-C8),"n.a.") -> n.a. | E20: =IFERROR(-E19/(E8-D8),"n.a.") -> 0 | F20: =IFERROR(-F19/(F8-E8),"n.a.") -> 0 | G20: =IFERROR(-G19/(G8-F8),"n.a.") -> 0 | H20: =IFERROR(-H19/(H8-G8),"n.a.") -> 0 | I20: =IFERROR(-I19/(I8-H8),"n.a.") -> 0 | J20: =IFERROR(-J19/(J8-I8),"n.a.") -> 0 | L20: -0.11510094 | M20: -0.013836661 | N20: 0.0064699555 | O20: 0.096134057 | P20: 0.11564435
B22: Net Capital expenditure | F22: =CFS!C20*10^6 -> 0 | G22: =CFS!D20*10^6 -> 0 | H22: =CFS!E20*10^6 -> 0 | I22: =CFS!F20*10^6 -> 0 | J22: =CFS!G20*10^6 -> 0 | L22: -57667500 | M22: -78900000 | N22: -104340000 | O22: -158017500 | P22: -193905000
B23: As % of revenue | E23: =IFERROR(-E22/E8,"n.a.") -> 0 | F23: =IFERROR(-F22/F8,"n.a.") -> 0 | G23: =IFERROR(-G22/G8,"n.a.") -> 0 | H23: =IFERROR(-H22/H8,"n.a.") -> 0 | I23: =IFERROR(-I22/I8,"n.a.") -> 0 | J23: =IFERROR(-J22/J8,"n.a.") -> 0 | L23: 0.43240639 | M23: 0.32756497 | N23: 0.26705622 | O23: 0.20267754 | P23: 0.16523321
B24: FCFF | C24: =+C15+C17+C19+C22 -> 0 | D24: =+D15+D17+D19+D22 -> 0 | E24: =+E15+E17+E19+E22 -> 66.97 | F24: =+F15+F17+F19+F22 -> 81.270315 | G24: =+G15+G17+G19+G22 -> 109.17238 | H24: =+H15+H17+H19+H22 -> 144.02414 | I24: =+I15+I17+I19+I22 -> 168.24026 | J24: =+J15+J17+J19+J22 -> 197.18766 | L24: -36502334 | M24: -46563643 | N24: -51539613 | O24: -29831645 | P24: 92501374
B25: Growth (%) | G25: =+IFERROR(G24/F24-1,"n.a.") -> 0.34332425 | H25: =+IFERROR(H24/G24-1,"n.a.") -> 0.31923597 | I25: =+IFERROR(I24/H24-1,"n.a.") -> 0.1681393 | J25: =+IFERROR(J24/I24-1,"n.a.") -> 0.1720599 | L25: 5.4367204 | M25: 0.27563468 | N25: 0.10686383 | O25: -0.42118996 | P25: -4.1007802
B27: Year factor | F27: 1 | G27: 2 | H27: 3 | I27: 4 | J27: 5 | L27: 1 | M27: 2 | N27: 3 | O27: 4.0027397 | P27: 5.0027397
B28: PV factor | F28: =IFERROR(1/(1+$D$41)^(F27),"n.a.") -> 0.82560021 | G28: =IFERROR(1/(1+$D$41)^(G27),"n.a.") -> 0.68161571 | H28: =IFERROR(1/(1+$D$41)^(H27),"n.a.") -> 0.56274207 | I28: =IFERROR(1/(1+$D$41)^(I27),"n.a.") -> 0.46459997 | J28: =IFERROR(1/(1+$D$41)^(J27),"n.a.") -> 0.38357384 | L28: 0.8343763 | M28: 0.69618382 | N28: 0.58087928 | O28: 0.48443153 | P28: 0.40419819
B29: PV of FCFF | F29: =IFERROR(F28*F24,"n.a.") -> 67.096789 | G29: =IFERROR(G28*G24,"n.a.") -> 74.413613 | H29: =IFERROR(H28*H24,"n.a.") -> 81.048442 | I29: =IFERROR(I28*I24,"n.a.") -> 78.164418 | J29: =IFERROR(J28*J24,"n.a.") -> 75.636026 | L29: -30456683 | M29: -32416855 | N29: -29938293 | O29: -14451389 | P29: 37388888
B31: WACC | F31: Equity Value | L31: WACC | P31: Equity Value
B32: Risk free rate | D32: 0.065 | F32: Total PV of FCFF | H32: =SUM(F29:J29) -> 376.35929 | L32: Risk free rate | N32: 0.065 | P32: Total PV of FCFF | R32: =SUM(L29:P29) -> -69874332
B33: Beta | D33: 1 | F33: Terminal Value | H33: =+J24*(1+H35)/(D41-H35) -> 1051.7225 | L33: Beta | N33: 1 | P33: Terminal Value | R33: =+P24*(1+R35)/(N41-R35) -> 5.4676712e+08
B34: Equity risk premium | D34: 0.085 | F34: Terminal Value PV Factor | H34: =+J28 -> 0.38357384 | L34: Equity risk premium | N34: 0.085 | P34: Terminal Value PV Factor | R34: 0.40419819
B35: Size premium | D35: 0.05 | F35: Terminal Growth Rate | H35: 0.02 | I35: Based on Industry | L35: Size premium | N35: 0.05 | P35: Terminal Growth Rate | R35: 0.035
B36: Company Specific Risk Premium | D36: 0.04 | F36: PV of Terminal Value | H36: =+H33*H34 -> 403.41323 | L36: Company Specific Risk Premium | N36: 0.05 | P36: PV of Terminal Value | R36: =+R33*R34 -> 2.2100228e+08
B37: Cost of equity | D37: =+D32+D34*D33+D36+D35 -> 0.24 | F37: Add: Cash and short term investments | L37: Cost of equity | N37: =+N32+N34*N33+N36+N35 -> 0.25 | P37: Add: Cash and short term investments | R37: 1310657
B38: Cost of debt | D38: 0.13 | F38: Less: Debt | L38: Cost of debt | N38: 0.15 | P38: Less: Debt | R38: 44327873
B39: Debt/(Debt+Equity) ratio | D39: 0.2 | F39: Equity Value (Post-money) | H39: =+SUM(H36:H38)+H32 -> 779.77252 | L39: Debt/(Debt+Equity) ratio | N39: 0.3 | P39: Equity Value (Post-money) | R39: =+SUM(R36:R38)+R32 -> 1.9676648e+08
B40: Tax rate | D40: 0.26 | L40: Tax rate | N40: 0.22
B41: WACC | D41: =+D37*(1-D39)+D38*(1-D40)*D39 -> 0.21124 | F41: Equity Investment | L41: WACC | N41: =+N37*(1-N39)+N38*(1-N40)*N39 -> 0.2101 | P41: Equity Investment | R41: =H41 -> 0
F42: Equity Value (Pre-money) | H42: =H39-H41 -> 779.77252 | P42: Equity Value (Pre-money) | R42: =R39-R41 -> 1.9676648e+08

Sheet Weighted Average Valuation
F10: <<Kindly prepare as taught in class>>

Sheet Sheet1
Q14: =20/70 -> 0.28571429 | R14: =30/70 -> 0.42857143
P19: =100/70 -> 1.4285714

Sheet Districtwise_Rajasthan farmers
B2: Districts wise Cropped Area (hectares) and Agriculure workers
C3: 2011-14
B4: Districts | C4: Cropped Area (hectare) | D4: Agriculture Worker
A5: 1 | B5: Ajmer | C5: 606218 | D5: 444379
A6: 2 | B6: Alwar | C6: 778883 | D6: 1115663 | E6: =D6+D18+D22+D25+D27+D28 -> 5489413
A7: 3 | B7: Banswara | C7: 298241 | D7: 745939
A8: =A7+1 -> 4 | B8: Barmer | C8: 947904 | D8: 886956
A9: =A8+1 -> 5 | B9: Bharatpur | C9: 538568 | D9: 739888
A10: =A9+1 -> 6 | B10: Bhilwara | C10: 510976 | D10: 718220
A11: =A10+1 -> 7 | B11: Bikaner | C11: 610854 | D11: 603056
A12: =A11+1 -> 8 | B12: Bundi | C12: 302348 | D12: 361841
A13: =A12+1 -> 9 | B13: Chittorgarh | C13: 371924 | D13: 576670
A14: =A13+1 -> 10 | B14: Churu | C14: 757936 | D14: 660627
A15: =A14+1 -> 11 | B15: Dholpur | C15: 224138 | D15: 304278
A16: =A15+1 -> 12 | B16: Dungarpur | C16: 171086 | D16: 412179
A17: =A16+1 -> 13 | B17: Ganganagar | C17: 1519306 | D17: 1036020
A18: =A17+1 -> 14 | B18: Jaipur | C18: 1297949 | D18: 1343134
A19: =A18+1 -> 15 | B19: Jaisalmer | C19: 323464 | D19: 176338
... A31: =A30+1 -> 27 | B31: Udaipur | C31: 577162 | D31: 1559477
B32: Total | C32: =SUM(C5:C31) -> 16430306 | D32: =SUM(D5:D31) -> 18558534 | E32: =C32/D32 -> 0.88532349 | F32: 58 | G32: =C32/F32 -> 283281.14 | H32: =D32/F32 -> 319974.72
B34: Agricultural workers here include both cultivators and agricultural labourers (main and marginal & rural and urban).
F39: Should be included in Insutry Make up / State wide infrmation tab

Sheet Statewise_Agri Data (2)
B1: STATEWISE DEMOGRAPHIC AND AGRICULTURE DATA
C2: Geogrophical Area (Lakh Sq. Km) | D2: Number of Total Districts | E2: Number of Farmers | F2: Average Size of Land Holdings (Hectares) | G2: Arable Land/ Cropped Area (Hectares) | H2: Crops grown | I2: Prominent Crop | J2: Number of Soil Testing / Advisory | K2: Number of Input Sellers | L2: Number of APMC | M2: Number of Crop Insurance providers? Penetration?
B3: India | C3: 32.87 | D3: 739 | E3: =(118.7+144.3)*10^6 -> 263000000 | F3: 1.08 | G3: 156463000 | J3: 3887 | L3: 2477 and 4843 sub-market yards
B4: Rajasthan | C4: 3.42 | D4: 27 | E4: 18558534 | F4: 3.07 | G4: 16430306 | H4: bajra, jowar, maize, barley, wheat, pulses, gram, cotton,groundnut, sugarcane, rapeseed, mustard and sesame | I4: Bajra, Rapeseed and Mustard Oil | J4: 203 | L4: 144 | M4: 5
B5: Haryana | C5: =44212/10^5 -> 0.44212 | D5: 22 | E5: =16.17*10^5 -> 1617000 | F5: 2.25 | G5: 3676000 | H5: sugarcane, groundnut, maize and paddy, chillies, bajra, jawar, pulses and vegetables | I5: Wheat, Rice, Maize and Bajra | J5: 65 | L5: 81
B6: Madhya Pradesh | C6: 3.08 | D6: 50 | E6: =(110.38+74.01)*10^5 -> 18439000 | F6: 2.3 | G6: =203*10^5 -> 20300000 | H6: Soybean, wheat, gram, paddy, cotton, jowar, maize, arhar, urad, moong, groundnut, mustard, sesamum. | I6: Wheat, Rice, Cotton, Pulses, Soyabean | J6: 103 | L6: 80
B7: Uttar Pradesh | C7: 2.4 | D7: 75 | E7: =233.25*10^5 -> 23325000 | F7: 0.8 | G7: =19.218*10^6 -> 19218000 | H7: rice, maize, pigeon pea, sorghum, pearl millet, moong beans, Bengal gram, green peas, rapeseed and mustard and lentil | I7: Rice, wheat, Sugarcane | J7: 180 | L7: 250
B8: Punjab | C8: =50362/10^5 -> 0.50362 | D8: 22 | E8: 1058000 | F8: 3.62 | G8: =7.442*10^6 -> 7442000 | H8: Rice, Wheat, Cotton, Maize, Sugarcane, Potato, Pulses | I8: Rice, Wheat, Cotton, Maize | J8: 149 | L8: 37
B9: Total | D9: =SUM(D4:D8) -> 196 | E9: =SUM(E4:E8) -> 62997534 | G9: =SUM(G4:G8) -> 67066306 | H9: =SUM(H4:H8) -> 0 | J9: =SUM(J4:J8) -> 700 | K9: =SUM(K4:K8) -> 0 | L9: =SUM(L4:L8) -> 592 | M9: =SUM(M4:M8) -> 5
B11: What is your source?
B12: Note
B13: 1. Rajasthan data pertains to 2011 | E13: =7.78+3.15+5.24 -> 16.17
B14: 2. Haryana data pertains to 2015, 2011
B15: 3. Punjab data pertains to 2015, 2011
B16: 4. MP data pertains to 2013
B17: 5. UP data pertains to 2011, 2013
B18: 6. Soil Testing Lab details as per Farmers Portal - https://farmer.gov.in/stl.aspx
B21: RAJASTHAN
B23: Districts wise Cropped Area (hectares) and Agriculure workers
C24: 2011-14
B25: Districts | C25: Cropped Area (hectare) | D25: Agriculture Worker
A26: 1 | B26: Ajmer | C26: 606218 | D26: 444379
A27: 2 | B27: Alwar | C27: 778883 | D27: 1115663
A28: 3 | B28: Banswara | C28: 298241 | D28: 745939
A29: =A28+1 -> 4 | B29: Barmer | C29: 947904 | D29: 886956
A30: =A29+1 -> 5 | B30: Bharatpur | C30: 538568 | D30: 739888
A31: =A30+1 -> 6 | B31: Bhilwara | C31: 510976 | D31: 718220
A32: =A31+1 -> 7 | B32: Bikaner | C32: 610854 | D32: 603056
A33: =A32+1 -> 8 | B33: Bundi | C33: 302348 | D33: 361841
A34: =A33+1 -> 9 | B34: Chittorgarh | C34: 371924 | D34: 576670
A35: =A34+1 -> 10 | B35: Churu | C35: 757936 | D35: 660627
A36: =A35+1 -> 11 | B36: Dholpur | C36: 224138 | D36: 304278
A37: =A36+1 -> 12 | B37: Dungarpur | C37: 171086 | D37: 412179
A38: =A37+1 -> 13 | B38: Ganganagar | C38: 1519306 | D38: 1036020
A39: =A38+1 -> 14 | B39: Jaipur | C39: 1297949 | D39: 1343134
A40: =A39+1 -> 15 | B40: Jaisalmer | C40: 323464 | D40: 176338
... A52: =A51+1 -> 27 | B52: Udaipur | C52: 577162 | D52: 1559477
B53: Total | C53: =SUM(C26:C52) -> 16430306 | D53: =SUM(D26:D52) -> 18558534
B55: Agricultural workers here include both cultivators and agricultural labourers (main and marginal & rural and urban).
